Workbook

Sheet Account_Setup_and_Data_Load
A1: Organization Link | B1: Organization | C1: Location | D1: Location Ref | E1: Account Style Link | F1: Account Style Caption | G1: Account Subtype | H1: Account Number | I1: Account Reference | J1: Account Supplier | K1: Account Reader | L1: Record Start YYYY-MM-DD | M1: Record End YYYY-MM-DD | N1: Record Data Quality | O1: Record Billing Type | P1: Record Subtype | Q1: Record Entry Method | R1: Record Reference | S1: Record Invoice Number | T1: Quantity | U1: Total Cost
A2: 37395 | B2: Downer | C2: REV_Allied Asphalt | D2: AASPHT | E2: 7868 | F2: Revenue - AUD Million | H2: FY27REV_Allied Asphalt | I2: FY27REV_Allied Asphalt | J2: Downer | K2: Revenue | L2: 2026-07-01 | M2: 2026-07-31 | N2: Actual | O2: Standard | Q2: Insert | R2: Allied Asphalt | S2: Allied Asphalt | T2: 0
A3: 37395 | B3: Downer | C3: REV_BIA | D3: RSV175-1 | E3: 7868 | F3: Revenue - AUD Million | H3: FY27REV_BIA | I3: FY27REV_BIA | J3: Downer | K3: Revenue | L3: 2026-07-01 | M3: 2026-07-31 | N3: Actual | O3: Standard | Q3: Insert | R3: BIA | S3: BIA | T3: -3.8
A4: 37395 | B4: Downer | C4: REV_EDI Rail- Bombardier Transportation | D4: ERBT | E4: 7868 | F4: Revenue - AUD Million | H4: FY27REV_EDI Rail- Bombardier Transportation | I4: FY27REV_EDI Rail- Bombardier Transportation | J4: Downer | K4: Revenue | L4: 2026-07-01 | M4: 2026-07-31 | N4: Actual | O4: Standard | Q4: Insert | R4: EDI Rail- Bombardier Transportation | S4: EDI Rail- Bombardier Transportation | T4: -3.4
A5: 37395 | B5: Downer | C5: REV_Emulco | D5: EMU | E5: 7868 | F5: Revenue - AUD Million | H5: FY27REV_Emulco | I5: FY27REV_Emulco | J5: Downer | K5: Revenue | L5: 2026-07-01 | M5: 2026-07-31 | N5: Actual | O5: Standard | Q5: Insert | R5: Emulco | S5: Emulco | T5: 0
A6: 37395 | B6: Downer | C6: REV_Isaac Asphalt | D6: ISAAT | E6: 7868 | F6: Revenue - AUD Million | H6: FY27REV_Isaac Asphalt | I6: FY27REV_Isaac Asphalt | J6: Downer | K6: Revenue | L6: 2026-07-01 | M6: 2026-07-31 | N6: Actual | O6: Standard | Q6: Insert | R6: Isaac Asphalt | S6: Isaac Asphalt | T6: 0

Sheet Prep - with formulas
A1: Organization Link | B1: Organization | C1: Location | D1: Location Ref | E1: Account Style Link | F1: Account Style Caption | G1: Account Subtype | H1: Account Number | I1: Account Reference | J1: Account Supplier | K1: Account Reader | L1: Record Start YYYY-MM-DD | M1: Record End YYYY-MM-DD | N1: Record Data Quality | O1: Record Billing Type | P1: Record Subtype | Q1: Record Entry Method | R1: Record Reference | S1: Record Invoice Number | T1: Quantity
A2: 37395 | B2: Downer | C2: =CONCATENATE("REV_",'FY27 JV Rev'!$A2) -> REV_Allied Asphalt | D2: =IFERROR(INDEX('Extract_for_Locations 26 Aug 26'!$E:$E,MATCH(C2,'Extract_for_Locations 26 Aug 26'!$B:$B,0)),IFERROR(INDEX('Extract_for_Locations 26 Aug 26'!$E:$E,MATCH("_CLOSED_"&C2,'Extract_for_Locations 26 Aug 26'!$B:$B,0)),"")) -> AASPHT | E2: 7868 | F2: Revenue - AUD Million | H2: =CONCATENATE("FY27REV_",'FY27 JV Rev'!$A2) -> FY27REV_Allied Asphalt | I2: =CONCATENATE("FY27REV_",'FY27 JV Rev'!$A2) -> FY27REV_Allied Asphalt | J2: Downer | K2: Revenue | L2: 2026-07-01 | M2: 2026-07-31 | N2: Actual | O2: Standard | Q2: Insert | R2: ='FY27 JV Rev'!$A2 -> Allied Asphalt | S2: ='FY27 JV Rev'!$A2 -> Allied Asphalt | T2: =-'FY27 JV Rev'!B2 -> 0
A3: 37395 | B3: Downer | C3: =CONCATENATE("REV_",'FY27 JV Rev'!$A3) -> REV_BIA | D3: =IFERROR(INDEX('Extract_for_Locations 26 Aug 26'!$E:$E,MATCH(C3,'Extract_for_Locations 26 Aug 26'!$B:$B,0)),IFERROR(INDEX('Extract_for_Locations 26 Aug 26'!$E:$E,MATCH("_CLOSED_"&C3,'Extract_for_Locations 26 Aug 26'!$B:$B,0)),"")) -> RSV175-1 | E3: 7868 | F3: Revenue - AUD Million | H3: =CONCATENATE("FY27REV_",'FY27 JV Rev'!$A3) -> FY27REV_BIA | I3: =CONCATENATE("FY27REV_",'FY27 JV Rev'!$A3) -> FY27REV_BIA | J3: Downer | K3: Revenue | L3: 2026-07-01 | M3: 2026-07-31 | N3: Actual | O3: Standard | Q3: Insert | R3: ='FY27 JV Rev'!$A3 -> BIA | S3: ='FY27 JV Rev'!$A3 -> BIA | T3: =-'FY27 JV Rev'!B3 -> -3.8
A4: 37395 | B4: Downer | C4: =CONCATENATE("REV_",'FY27 JV Rev'!$A4) -> REV_EDI Rail- Bombardier Transportation | D4: =IFERROR(INDEX('Extract_for_Locations 26 Aug 26'!$E:$E,MATCH(C4,'Extract_for_Locations 26 Aug 26'!$B:$B,0)),IFERROR(INDEX('Extract_for_Locations 26 Aug 26'!$E:$E,MATCH("_CLOSED_"&C4,'Extract_for_Locations 26 Aug 26'!$B:$B,0)),"")) -> ERBT | E4: 7868 | F4: Revenue - AUD Million | H4: =CONCATENATE("FY27REV_",'FY27 JV Rev'!$A4) -> FY27REV_EDI Rail- Bombardier Transportation | I4: =CONCATENATE("FY27REV_",'FY27 JV Rev'!$A4) -> FY27REV_EDI Rail- Bombardier Transportation | J4: Downer | K4: Revenue | L4: 2026-07-01 | M4: 2026-07-31 | N4: Actual | O4: Standard | Q4: Insert | R4: ='FY27 JV Rev'!$A4 -> EDI Rail- Bombardier Transportation | S4: ='FY27 JV Rev'!$A4 -> EDI Rail- Bombardier Transportation | T4: =-'FY27 JV Rev'!B4 -> -3.4
A5: 37395 | B5: Downer | C5: =CONCATENATE("REV_",'FY27 JV Rev'!$A5) -> REV_Emulco | D5: =IFERROR(INDEX('Extract_for_Locations 26 Aug 26'!$E:$E,MATCH(C5,'Extract_for_Locations 26 Aug 26'!$B:$B,0)),IFERROR(INDEX('Extract_for_Locations 26 Aug 26'!$E:$E,MATCH("_CLOSED_"&C5,'Extract_for_Locations 26 Aug 26'!$B:$B,0)),"")) -> EMU | E5: 7868 | F5: Revenue - AUD Million | H5: =CONCATENATE("FY27REV_",'FY27 JV Rev'!$A5) -> FY27REV_Emulco | I5: =CONCATENATE("FY27REV_",'FY27 JV Rev'!$A5) -> FY27REV_Emulco | J5: Downer | K5: Revenue | L5: 2026-07-01 | M5: 2026-07-31 | N5: Actual | O5: Standard | Q5: Insert | R5: ='FY27 JV Rev'!$A5 -> Emulco | S5: ='FY27 JV Rev'!$A5 -> Emulco | T5: =-'FY27 JV Rev'!B5 -> 0
A6: 37395 | B6: Downer | C6: =CONCATENATE("REV_",'FY27 JV Rev'!$A6) -> REV_Isaac Asphalt | D6: =IFERROR(INDEX('Extract_for_Locations 26 Aug 26'!$E:$E,MATCH(C6,'Extract_for_Locations 26 Aug 26'!$B:$B,0)),IFERROR(INDEX('Extract_for_Locations 26 Aug 26'!$E:$E,MATCH("_CLOSED_"&C6,'Extract_for_Locations 26 Aug 26'!$B:$B,0)),"")) -> ISAAT | E6: 7868 | F6: Revenue - AUD Million | H6: =CONCATENATE("FY27REV_",'FY27 JV Rev'!$A6) -> FY27REV_Isaac Asphalt | I6: =CONCATENATE("FY27REV_",'FY27 JV Rev'!$A6) -> FY27REV_Isaac Asphalt | J6: Downer | K6: Revenue | L6: 2026-07-01 | M6: 2026-07-31 | N6: Actual | O6: Standard | Q6: Insert | R6: ='FY27 JV Rev'!$A6 -> Isaac Asphalt | S6: ='FY27 JV Rev'!$A6 -> Isaac Asphalt | T6: =-'FY27 JV Rev'!B6 -> 0

Sheet FY27 JV Rev
A1: Joint Venture and Associates | B1: Jul
A2: Allied Asphalt | B2: 0
A3: BIA | B3: 3.8
A4: EDI Rail- Bombardier Transportation | B4: 3.4
A5: Emulco | B5: 0
A6: Isaac Asphalt | B6: 0
A8: Group | B8: 7.2
A9: Check | B9: =B8-SUM(B2:B6) -> 0

Sheet FY27 JV Revenue
A1: FY27 JV Revenue — Joint Ventures & Associates (Jul 26 – Jun 27; one month deep: Jul 26)
A2: Source: sheet "FY27 JV Rev" (copied verbatim into this workbook from "Actual Revenue Jul 26 -unlinked.xlsx"). Cells below link to it. The Account_Setup_and_Data_Load sheet carries these same amounts NEGATED, to exclude JV revenue from all revenue figures — see "Prep - with formulas" for the row-by-row linking.
A4: Joint Venture and Associates | B4: Jul 26 | C4: FY27 Total | D4: Location Ref | E4: Already in FY27 revenue upload?
A5: Allied Asphalt | B5: ='FY27 JV Rev'!B2 -> 0 | C5: =SUM(B5:B5) -> 0 | D5: =IFERROR(INDEX('Extract_for_Locations 26 Aug 26'!$E:$E,MATCH("REV_"&$A5,'Extract_for_Locations 26 Aug 26'!$B:$B,0)),IFERROR(INDEX('Extract_for_Locations 26 Aug 26'!$E:$E,MATCH("_CLOSED_"&"REV_"&$A5,'Extract_for_Locations 26 Aug 26'!$B:$B,0)),"")) -> AASPHT | E5: No — see note 4
A6: BIA | B6: ='FY27 JV Rev'!B3 -> 3.8 | C6: =SUM(B6:B6) -> 3.8 | D6: =IFERROR(INDEX('Extract_for_Locations 26 Aug 26'!$E:$E,MATCH("REV_"&$A6,'Extract_for_Locations 26 Aug 26'!$B:$B,0)),IFERROR(INDEX('Extract_for_Locations 26 Aug 26'!$E:$E,MATCH("_CLOSED_"&"REV_"&$A6,'Extract_for_Locations 26 Aug 26'!$B:$B,0)),"")) -> RSV175-1 | E6: Yes — inside the REV_Transport & Infrastructure AU roll-up, see note 4
A7: EDI Rail- Bombardier Transportation | B7: ='FY27 JV Rev'!B4 -> 3.4 | C7: =SUM(B7:B7) -> 3.4 | D7: =IFERROR(INDEX('Extract_for_Locations 26 Aug 26'!$E:$E,MATCH("REV_"&$A7,'Extract_for_Locations 26 Aug 26'!$B:$B,0)),IFERROR(INDEX('Extract_for_Locations 26 Aug 26'!$E:$E,MATCH("_CLOSED_"&"REV_"&$A7,'Extract_for_Locations 26 Aug 26'!$B:$B,0)),"")) -> ERBT | E7: Yes — as the "WA JV" line under TLS Fleet, inside the REV_Passenger Through Life Support roll-up, see note 4
A8: Emulco | B8: ='FY27 JV Rev'!B5 -> 0 | C8: =SUM(B8:B8) -> 0 | D8: =IFERROR(INDEX('Extract_for_Locations 26 Aug 26'!$E:$E,MATCH("REV_"&$A8,'Extract_for_Locations 26 Aug 26'!$B:$B,0)),IFERROR(INDEX('Extract_for_Locations 26 Aug 26'!$E:$E,MATCH("_CLOSED_"&"REV_"&$A8,'Extract_for_Locations 26 Aug 26'!$B:$B,0)),"")) -> EMU | E8: No — see note 4
A9: Isaac Asphalt | B9: ='FY27 JV Rev'!B6 -> 0 | C9: =SUM(B9:B9) -> 0 | D9: =IFERROR(INDEX('Extract_for_Locations 26 Aug 26'!$E:$E,MATCH("REV_"&$A9,'Extract_for_Locations 26 Aug 26'!$B:$B,0)),IFERROR(INDEX('Extract_for_Locations 26 Aug 26'!$E:$E,MATCH("_CLOSED_"&"REV_"&$A9,'Extract_for_Locations 26 Aug 26'!$B:$B,0)),"")) -> ISAAT | E9: No — see note 4
A10: Group | B10: =SUM(B5:B9) -> 7.2 | C10: =SUM(C5:C9) -> 7.2
A12: Notes
A13: 1. Purpose: JV and associate revenue is to be excluded from all revenue figures. This workbook uploads the JV revenue as negative values against JV-specific locations, so revenue reporting nets to revenue excluding JV revenue. It is the FY27 counterpart of Account_Setup_and_Data_Load_-_PM&C_JVREVJUL25toJUN26_Setup.xlsx (FY26), one month deep so far (Jul 26); extend it month by month alongside the main FY27 setup workbook.
A14: 2. Locations: per the "Extract_for_Locations 26 Aug 26" sheet (copied verbatim into this workbook from the FY27 setup workbook), all five JV revenue locations exist in Envizi as open "REV_<name>" locations — they were reopened for the FY26 exclusion load, so unlike FY26 no reopening/renaming is needed before loading. Each carries both the Classification (Operational Control) and Portfolio (Revenue) memberships. The Location Refs in column D are derived from that extract by INDEX/MATCH (matching "REV_<name>", with the FY26 fallback to "_CLOSED_REV_<name>" retained in case a location is ever closed again), as is column D of "Prep - with formulas".
A15: 3. Sign convention: the monthly figures on this sheet are JV revenue as reported (positive), linked from the verbatim "FY27 JV Rev" source sheet. The negation is applied in "Prep - with formulas" (Quantity column: =-'FY27 JV Rev'!<cell>) and the upload sheet carries the resulting values. Values of zero are loaded as 0.
A16: 4. Coverage — CONFIRMED 27 Aug 26: all five JVs are uploaded as negatives at the JV-source figures, matching the FY26 treatment (coverage there confirmed 4 Aug 26), on the basis that JV revenue is included in the main revenue tab by default. For Jul 26: BIA (3.8) is in the loaded FY27 revenue rolled into REV_Transport & Infrastructure AU (the FY27 workbook rolls to Sub-LOB × Level 2, and BIA is a Level 2 under Transport & Infrastructure AU); EDI Rail- Bombardier Transportation is in it as the "WA JV" line under TLS Fleet, rolled into REV_Passenger Through Life Support. Allied Asphalt, Emulco and Isaac Asphalt are zero in Jul 26; in months where they are non-zero their revenue sits inside the divisional lines rather than as own lines.
A17: 4a. Rounding: the deduction uses the JV-source figures, which can differ from the main tab by rounding — for Jul 26, "WA JV" is 3.5 in the main tab but EDI is 3.4 on the JV sheet, leaving a 0.1 residual in net revenue. Same class of residual as FY26 (note 4a there: BIA 69.9 vs 70.1). NOTE the FY26 workbook's note 4 states EDI Rail- Bombardier was "not previously included" in the FY26 figures — that is incorrect: it is included there too, as the "WA JV" line under RTS > TLS Fleet (35.9 in FY26 vs 35.6 deducted). The FY26 loaded amounts are unaffected; only that note's rationale is wrong.
A18: 5. Keolis Downer JV: not on the "FY27 JV Rev" source sheet. Per the FY26 decision (confirmed 4 Aug 26), the source sheet is the agreed definition of JV revenue to exclude, so Keolis Downer revenue stays in revenue.
A19: 6. Accounts: the five FY27REV_<name> accounts do not exist yet in the 26 Aug 26 accounts extract (their FY26REV_ counterparts do, created by the FY26 exclusion load). Accounts do not need creating separately — this data load creates them alongside the records (Record Entry Method Insert).
A20: 7. BIA Location Ref: the extract shows Location Ref "RSV175-1" for REV_BIA, which looks like a Rail Services Victoria code. Copied faithfully from the extract, unchanged from FY26.

Sheet Extract_for_Locations 26 Aug 26
A1: Associate | B1: Location_Name | C1: Type | D1: Ref_No | E1: Location Ref | F1: Id | G1: Notes | H1: Address | I1: City | J1: State | K1: Postal_Code | L1: Address Country | M1: Region | N1: Country | O1: Alternate Factor Region | P1: Group Level 1 | Q1: Group Level 2 | R1: Group Level 3 | S1: Group_Associate | T1: Report_Percent | U1: Effective_From | V1: Effective_To | W1: Group_Type | X1: Latitude | Y1: Longitude | Z1: ANZSIC Code | AA1: Opened On | AB1: Closed On
A2: Downer | B2: .HOUR.LMC -RICHTER DRI'G PNG CENTURY R | C2: Other | D2: L9.MIN.UED.4501 | E2: 4501 | M2: Auckland | N2: New Zealand | P2: Operational Control | Q2: Operational Control | R2: Mining | S2: Downer | T2: 100.0000 | W2: Classification
A3: Downer | B3: .HOUR.RICHTER DRILLING - OK TEDI | C3: Other | D3: L9.MIN.UED.4502 | E3: 4502 | M3: Auckland | N3: New Zealand | P3: Operational Control | Q3: Operational Control | R3: Mining | S3: Downer | T3: 100.0000 | W3: Classification
A4: Downer | B4: [CLOSED] 4 Redwood Lane - Tauriko West Enabling Works | C4: Depot | D4: L9.DNZJ.553912 | E4: L9.DNZJ.553912 | M4: Bay of Plenty | N4: New Zealand | P4: Operational Control | Q4: Operational Control | R4: Transport & Infrastructure (T&I) | S4: Downer | T4: 100.0000 | W4: Classification | AB4: 2026/03/31
A5: Downer | B5: [CLOSED] Hobart Airport Upgrade Project | C5: Airport | D5: L9.J.170751 | E5: 170751 | G5: TI-170751 - Airports General Delivery | H5: 250 Surf Road, Seven Mile Beach | I5: Tasmania | J5: TAS | K5: 7170 | M5: Tasmania | N5: Australia | P5: Operational Control | Q5: Operational Control | R5: Transport & Infrastructure (T&I) | S5: Downer | T5: 100.0000 | W5: Classification | AB5: 2025/05/31
A6: Downer | B6: [CLOSED] Numurkah Solar Farm | C6: Other | D6: L9.J.381155 | E6: IP-39210265 | M6: Shepparton | N6: Australia | P6: Y_Non Operational Control | Q6: Y_Non Operational Control | R6: Energy and Utilities (EU) | S6: Downer | T6: 100.0000 | W6: Classification | X6: -37.819015 | Y6: 144.955762 | Z6: 310
A7: Downer | B7: _AI Testing | C7: Other | M7: North Ryde | N7: Australia | P7: Y_Non Operational Control | Q7: Y_Non Operational Control | R7: Corporate | S7: Downer | T7: 100.0000 | W7: Classification
A8: Downer | B8: _CLOSED_ AGIS Braddon | C8: Office | D8: L9.J.502002 | E8: 2001 | F8: 2001 | G8: electricity data only from landlord accounts | M8: Australian Capital Territory | N8: Australia | P8: Operational Control | Q8: Operational Control | R8: Social Infra & Citizen Serv (SICS) | S8: Downer | T8: 100.0000 | U8: 2018/11/01 | V8: 2021/10/31 | W8: Classification | X8: -35.273 | Y8: 149.133 | Z8: 760 | AA8: 2016/08/01 | AB8: 2022/12/06
A9: Downer | B9: _CLOSED_ North Ryde T1 - Level 2 | C9: Office | D9: L9.J.102001 | E9: 1012 | H9: T1, Triniti Business Campus, 39 Delhi Road | I9: Sydney | J9: NSW | K9: 2113 | M9: North Ryde | N9: Australia | P9: Operational Control | Q9: Operational Control | R9: Corporate | S9: Downer | T9: 100.0000 | W9: Classification | Z9: 729 | AB9: 1900/01/01
A10: Downer | B10: _CLOSED_ OSM_Waitaki | C10: Other | D10: L9.DNZJ.55876 | E10: 5088 | G10: Outside Space Management (Gardening) - New facilities established for more granular reporting and to reflect new structure for FY17. See facility named "NZ-Infrastructure Services" for historical data. | H10: Chelmer Street | I10: Oamaru | J10: Otago | K10: 2104 | L10: New Zealand | M10: Oamaru | N10: New Zealand | P10: Operational Control | Q10: Operational Control | R10: Transport & Infrastructure (T&I) | S10: Downer | T10: 100.0000 | W10: Classification | X10: -45.0978481999999 | Y10: 170.9606991 | Z10: 731 | AA10: 2017/07/01
A11: Downer | B11: _CLOSED_25820008 - Winneke Main Substation Switchboard Replacement | C11: Site | D11: L9.J.25820008 | E11: UTIL-25820008 | G11: Main Substation Switchboard Replacement - Project finished in September 2022. | M11: Victoria | N11: Australia | P11: Operational Control | Q11: Operational Control | R11: Energy and Utilities (EU) | S11: Downer | T11: 100.0000 | W11: Classification | AB11: 2022/10/01
A12: Downer | B12: _CLOSED_25820008 - Winneke Main Substation Switchboard Replacement | C12: Site | D12: L9.J.25820008 | E12: UTIL-25820008 | G12: Main Substation Switchboard Replacement - Project finished in September 2022. | M12: Victoria | N12: Australia | P12: Utilities | Q12: UTIL-252 - Water Services Projects NSW/VIC | R12: SFP JV | S12: Downer | T12: 100.0000 | W12: Portfolio | AB12: 2022/10/01
A13: Downer | B13: _CLOSED_25820012 - WTP 25W Lagoon Pond 1 HV and LV Renewals | C13: Site | D13: L9.J.25820012 | E13: UTIL-25820012 | G13: WTP 25W Lagoon Pond 1 HV and LV Renewals | M13: Victoria | N13: Australia | P13: Operational Control | Q13: Operational Control | R13: Energy and Utilities (EU) | S13: Downer | T13: 100.0000 | W13: Classification | AB13: 2024/12/03
A14: Downer | B14: _CLOSED_25820012 - WTP 25W Lagoon Pond 1 HV and LV Renewals | C14: Site | D14: L9.J.25820012 | E14: UTIL-25820012 | G14: WTP 25W Lagoon Pond 1 HV and LV Renewals | M14: Victoria | N14: Australia | P14: Utilities | Q14: UTIL-252 - Water Services Projects NSW/VIC | R14: SFP JV | S14: Downer | T14: 100.0000 | W14: Portfolio | AB14: 2024/12/03
A15: Downer | B15: _CLOSED_86 Collins St Tas | C15: Branch Office | D15: L9.J.105001 | E15: 9164 | G15: Level 12, 86 Collins Street HOBART TAS 7000 | M15: Hobart | N15: Australia | P15: Operational Control | Q15: Operational Control | R15: Corporate | S15: Downer | T15: 100.0000 | W15: Classification | Z15: 692
A16: Downer | B16: _CLOSED_Accommodation - NZ | C16: Hotel | D16: L9.WAU.000887 | E16: L9.WAU.000887 | M16: Auckland | N16: New Zealand | P16: Operational Control | Q16: Operational Control | R16: Corporate | S16: Downer | T16: 100.0000 | W16: Classification
A17: Downer | B17: _CLOSED_Accommodation NT | C17: Facility | E17: 9129 | G17: 55 BATTEN RD MARRARA | M17: Darwin | N17: Australia | P17: Z_HISTORICAL_Operational Control | Q17: Z_HISTORICAL_Operational Control | R17: Corporate | S17: Downer | T17: 100.0000 | W17: Classification
A18: Downer | B18: _CLOSED_ACES - North Queensland Region | C18: Depot | D18: L9.DUA.12005 | E18: L9.DUA.12005 | G18: Contract ended June 2022. | M18: Queensland | N18: Australia | P18: Operational Control | Q18: Operational Control | R18: Energy and Utilities (EU) | S18: Downer | T18: 100.0000 | W18: Classification | AB18: 2022/06/30
A19: Downer | B19: _CLOSED_ACT | C19: Plant | D19: L9.S.11000020 | E19: L9.S.11000020 | G19: Unallocated regional fuel accounts | H19: ACT | I19: ACT | J19: ACT | M19: Australian Capital Territory | N19: Australia | P19: Z_HISTORICAL_Operational Control | Q19: Z_HISTORICAL_Operational Control | R19: Corporate | S19: Downer | T19: 100.0000 | W19: Classification | Z19: 580
A20: Downer | B20: _CLOSED_Adelaide Light Rail - North Terrace Tramli | C20: Other | D20: L9.D.20143004 | E20: L9.D.20143004 | H20: SA | I20: Adelaide | J20: SA | M20: South Australia | N20: Australia | P20: DT Infrastructure Locations for reallocation | Q20: DT Infrastructure Locations for reallocation | R20: DT Infrastructure Locations for reallocation | S20: Downer | T20: 100.0000 | W20: Portfolio | X20: -34.921297 | Y20: 138.604655 | Z20: 310
A21: Downer | B21: _CLOSED_Adelaide Light Rail - North Terrace Tramli | C21: Other | D21: L9.D.20143004 | E21: L9.D.20143004 | H21: SA | I21: Adelaide | J21: SA | M21: South Australia | N21: Australia | P21: Operational Control | Q21: Operational Control | R21: DT Infrastructure (pre Sept 23 divestment) | S21: Downer | T21: 100.0000 | V21: 2023/09/30 | W21: Classification | X21: -34.921297 | Y21: 138.604655 | Z21: 310
A22: Downer | B22: _CLOSED_Adelaide Light Rail - North Terrace Tramli | C22: Other | D22: L9.D.20143004 | E22: L9.D.20143004 | H22: SA | I22: Adelaide | J22: SA | M22: South Australia | N22: Australia | P22: Y_Non Operational Control | Q22: Y_Non Operational Control | R22: DT Infrastructure (post Sept Divestment) | S22: Downer | T22: 100.0000 | U22: 2023/10/01 | W22: Classification | X22: -34.921297 | Y22: 138.604655 | Z22: 310
A23: Downer | B23: _CLOSED_AE Smith - Burleigh | C23: Branch Office | D23: L9.S.13000757 | E23: 9165 | G23: 12/8 Fortitude Crescent BURLEIGH HEADS QLD 4220 | M23: New South Wales | N23: Australia | P23: ADS Backup | Q23: ADS Backup | R23: ADS Backup | S23: Downer | T23: 100.0000 | W23: Portfolio | Z23: 692
A24: Downer | B24: _CLOSED_AE Smith - Burleigh | C24: Branch Office | D24: L9.S.13000757 | E24: 9165 | G24: 12/8 Fortitude Crescent BURLEIGH HEADS QLD 4220 | M24: New South Wales | N24: Australia | P24: Operational Control | Q24: Operational Control | R24: Asset & Development Services (Baseline) | S24: Downer | T24: 100.0000 | V24: 2023/06/30 | W24: Classification | Z24: 692
A25: Downer | B25: _CLOSED_AE Smith - Burleigh | C25: Branch Office | D25: L9.S.13000757 | E25: 9165 | G25: 12/8 Fortitude Crescent BURLEIGH HEADS QLD 4220 | M25: New South Wales | N25: Australia | P25: Z_DIVESTED_Operational Control | Q25: Z_DIVESTED_Operational Control | R25: Asset & Development Services (FY24 & Beyond) | S25: Downer | T25: 100.0000 | U25: 2023/07/01 | W25: Classification | Z25: 692
A26: Downer | B26: _CLOSED_AE Smith - Canning Vale | C26: Wharf | D26: L9.S.16015134 | E26: Loc Ref | H26: 15 Canvale Rd | I26: Canning Vale | J26: WA | K26: 6155 | L26: Australia | M26: Western Australia | N26: Australia | P26: Z_HISTORICAL_Operational Control | Q26: Z_HISTORICAL_Operational Control | R26: Asset & Development Services (ADS) | S26: Downer | T26: 100.0000 | W26: Classification
A27: Downer | B27: _CLOSED_AE Smith - Eagle Farm | C27: Branch Office | D27: L9.S.16015125 | E27: 9013 | H27: Lot 801 65 Links Ave | I27: Eagle Farm | J27: QLD | K27: 4009 | M27: Queensland | N27: Australia | P27: ADS Backup | Q27: ADS Backup | R27: ADS Backup | S27: Downer | T27: 100.0000 | W27: Portfolio | X27: -27.436443 | Y27: 153.086368 | Z27: 692
A28: Downer | B28: _CLOSED_AE Smith - Eagle Farm | C28: Branch Office | D28: L9.S.16015125 | E28: 9013 | H28: Lot 801 65 Links Ave | I28: Eagle Farm | J28: QLD | K28: 4009 | M28: Queensland | N28: Australia | P28: Operational Control | Q28: Operational Control | R28: Asset & Development Services (Baseline) | S28: Downer | T28: 100.0000 | V28: 2023/06/30 | W28: Classification | X28: -27.436443 | Y28: 153.086368 | Z28: 692
A29: Downer | B29: _CLOSED_AE Smith - Eagle Farm | C29: Branch Office | D29: L9.S.16015125 | E29: 9013 | H29: Lot 801 65 Links Ave | I29: Eagle Farm | J29: QLD | K29: 4009 | M29: Queensland | N29: Australia | P29: Z_DIVESTED_Operational Control | Q29: Z_DIVESTED_Operational Control | R29: Asset & Development Services (FY24 & Beyond) | S29: Downer | T29: 100.0000 | U29: 2023/07/01 | W29: Classification | X29: -27.436443 | Y29: 153.086368 | Z29: 692
A30: Downer | B30: _CLOSED_AE Smith - Eagle Farm, Harvey St | C30: Office | D30: L9.S.13001004 | E30: 9128 | H30: Harvey St | I30: Eagle Farm | J30: QLD | K30: 4009 | M30: Brisbane | N30: Australia | P30: ADS Backup | Q30: ADS Backup | R30: ADS Backup | S30: Downer | T30: 100.0000 | W30: Portfolio | X30: -27.437252 | Y30: 153.093614 | Z30: 692
A31: Downer | B31: _CLOSED_AE Smith - Eagle Farm, Harvey St | C31: Office | D31: L9.S.13001004 | E31: 9128 | H31: Harvey St | I31: Eagle Farm | J31: QLD | K31: 4009 | M31: Brisbane | N31: Australia | P31: Operational Control | Q31: Operational Control | R31: Asset & Development Services (Baseline) | S31: Downer | T31: 100.0000 | V31: 2023/06/30 | W31: Classification | X31: -27.437252 | Y31: 153.093614 | Z31: 692
A32: Downer | B32: _CLOSED_AE Smith - Eagle Farm, Harvey St | C32: Office | D32: L9.S.13001004 | E32: 9128 | H32: Harvey St | I32: Eagle Farm | J32: QLD | K32: 4009 | M32: Brisbane | N32: Australia | P32: Z_DIVESTED_Operational Control | Q32: Z_DIVESTED_Operational Control | R32: Asset & Development Services (FY24 & Beyond) | S32: Downer | T32: 100.0000 | U32: 2023/07/01 | W32: Classification | X32: -27.437252 | Y32: 153.093614 | Z32: 692
A33: Downer | B33: _CLOSED_AE Smith - Eagle Farm, Schneider Rd | C33: Branch Office | D33: L9.S.13001052 | E33: 9127 | H33: 80 Schneider Road | I33: Eagle Farm | J33: QLD | K33: 4009 | L33: Australia | M33: Brisbane | N33: Australia | P33: ADS Backup | Q33: ADS Backup | R33: ADS Backup | S33: Downer | T33: 100.0000 | W33: Portfolio | X33: -27.423892 | Y33: 153.085062 | Z33: 692
A34: Downer | B34: _CLOSED_AE Smith - Eagle Farm, Schneider Rd | C34: Branch Office | D34: L9.S.13001052 | E34: 9127 | H34: 80 Schneider Road | I34: Eagle Farm | J34: QLD | K34: 4009 | L34: Australia | M34: Brisbane | N34: Australia | P34: Operational Control | Q34: Operational Control | R34: Asset & Development Services (Baseline) | S34: Downer | T34: 100.0000 | V34: 2023/06/30 | W34: Classification | X34: -27.423892 | Y34: 153.085062 | Z34: 692
A35: Downer | B35: _CLOSED_AE Smith - Eagle Farm, Schneider Rd | C35: Branch Office | D35: L9.S.13001052 | E35: 9127 | H35: 80 Schneider Road | I35: Eagle Farm | J35: QLD | K35: 4009 | L35: Australia | M35: Brisbane | N35: Australia | P35: Z_DIVESTED_Operational Control | Q35: Z_DIVESTED_Operational Control | R35: Asset & Development Services (FY24 & Beyond) | S35: Downer | T35: 100.0000 | U35: 2023/07/01 | W35: Classification | X35: -27.423892 | Y35: 153.085062 | Z35: 692
A36: Downer | B36: _CLOSED_AE Smith - Knoxfield | C36: Wharf | D36: L9.S.16012601 | H36: 10 Brand Rd | I36: Knoxfield | J36: VIC | K36: 3180 | M36: Victoria | N36: Australia | P36: Z_HISTORICAL_Operational Control | Q36: Z_HISTORICAL_Operational Control | R36: Asset & Development Services (ADS) | S36: Downer | T36: 100.0000 | W36: Classification
A37: Downer | B37: _CLOSED_AE Smith - Mackay | C37: Branch Office | D37: L9.S.3197.003.020.9M | E37: 9012 | H37: U4, 269 Richardson Rd | I37: Kawana | J37: QLD | K37: 4701 | L37: Australia | M37: Queensland | N37: Australia | P37: Z_HISTORICAL_Operational Control | Q37: Z_HISTORICAL_Operational Control | R37: Asset & Development Services (ADS) | S37: Downer | T37: 100.0000 | W37: Classification | Z37: 696
A38: Downer | B38: _CLOSED_AE Smith - Manunda | C38: Wharf | H38: 1/13 Donaldson St | I38: Manunda | J38: QLD | K38: 4870 | M38: Queensland | N38: Australia | P38: Z_HISTORICAL_Operational Control | Q38: Z_HISTORICAL_Operational Control | R38: Asset & Development Services (ADS) | S38: Downer | T38: 100.0000 | W38: Classification
A39: Downer | B39: _CLOSED_AE Smith - Mornington | C39: Branch Office | D39: L9.S.13001061 | E39: 9014 | H39: U 2 4 Yamada Place | I39: Mornington | J39: TAS | K39: 7018 | L39: Australia | M39: Tasmania | N39: Australia | P39: ADS Backup | Q39: ADS Backup | R39: ADS Backup | S39: Downer | T39: 100.0000 | W39: Portfolio | X39: -42.862696 | Y39: 147.399802 | Z39: 692
A40: Downer | B40: _CLOSED_AE Smith - Mornington | C40: Branch Office | D40: L9.S.13001061 | E40: 9014 | H40: U 2 4 Yamada Place | I40: Mornington | J40: TAS | K40: 7018 | L40: Australia | M40: Tasmania | N40: Australia | P40: Operational Control | Q40: Operational Control | R40: Asset & Development Services (Baseline) | S40: Downer | T40: 100.0000 | V40: 2023/06/30 | W40: Classification | X40: -42.862696 | Y40: 147.399802 | Z40: 692
...

Sheet Monthly Totals Check
A1: FY27 JV Revenue Exclusion — Monthly Totals: JV revenue (negated) vs Account Setup
A2: Each Account Setup monthly total must equal minus the JV revenue for that month. Extends by one row per month as FY27 fills out.
A3: Month | B3: JV Revenue (negated) | C3: Account Setup Total | D3: Difference | E3: Row Count (Setup) | F3: Status
A4: Jul 26 | B4: =-SUM('FY27 JV Rev'!B2:B6) -> -7.2 | C4: =SUMIFS(Account_Setup_and_Data_Load!$T:$T,Account_Setup_and_Data_Load!$L:$L,"2026-07-01") -> -7.2 | D4: =ROUND(C4-B4,4) -> 0 | E4: =COUNTIF(Account_Setup_and_Data_Load!$L:$L,"2026-07-01") -> 5 | F4: =IF(ABS(D4)<=0.001,"OK","MISMATCH") -> OK
A5: FY27 | B5: =SUM(B4:B4) -> -7.2 | C5: =SUM(C4:C4) -> -7.2 | D5: =ROUND(C5-B5,4) -> 0 | E5: =SUM(E4:E4) -> 5 | F5: =IF(ABS(D5)<=0.001,"OK","MISMATCH") -> OK

Sheet Check - By JV by Month
A1: Line-item check: Account Setup upload + source JV revenue = 0 for every JV and every month
A3: Joint Venture | B3: Jul 26 | C3: Status
A4: Allied Asphalt | B4: =ROUND(SUMIFS(Account_Setup_and_Data_Load!$T:$T,Account_Setup_and_Data_Load!$L:$L,"2026-07-01",Account_Setup_and_Data_Load!$R:$R,$A4)+'FY27 JV Rev'!B2,4) -> 0 | C4: =IF(SUMPRODUCT(ABS(B4:B4))<=0.001,"OK","MISMATCH") -> OK
A5: BIA | B5: =ROUND(SUMIFS(Account_Setup_and_Data_Load!$T:$T,Account_Setup_and_Data_Load!$L:$L,"2026-07-01",Account_Setup_and_Data_Load!$R:$R,$A5)+'FY27 JV Rev'!B3,4) -> 0 | C5: =IF(SUMPRODUCT(ABS(B5:B5))<=0.001,"OK","MISMATCH") -> OK
A6: EDI Rail- Bombardier Transportation | B6: =ROUND(SUMIFS(Account_Setup_and_Data_Load!$T:$T,Account_Setup_and_Data_Load!$L:$L,"2026-07-01",Account_Setup_and_Data_Load!$R:$R,$A6)+'FY27 JV Rev'!B4,4) -> 0 | C6: =IF(SUMPRODUCT(ABS(B6:B6))<=0.001,"OK","MISMATCH") -> OK
A7: Emulco | B7: =ROUND(SUMIFS(Account_Setup_and_Data_Load!$T:$T,Account_Setup_and_Data_Load!$L:$L,"2026-07-01",Account_Setup_and_Data_Load!$R:$R,$A7)+'FY27 JV Rev'!B5,4) -> 0 | C7: =IF(SUMPRODUCT(ABS(B7:B7))<=0.001,"OK","MISMATCH") -> OK
A8: Isaac Asphalt | B8: =ROUND(SUMIFS(Account_Setup_and_Data_Load!$T:$T,Account_Setup_and_Data_Load!$L:$L,"2026-07-01",Account_Setup_and_Data_Load!$R:$R,$A8)+'FY27 JV Rev'!B6,4) -> 0 | C8: =IF(SUMPRODUCT(ABS(B8:B8))<=0.001,"OK","MISMATCH") -> OK
A10: Overall | C10: =IF(SUMPRODUCT(ABS(B4:B8))<=0.001,"ALL OK","MISMATCH") -> ALL OK
